Workbook

Sheet BEHAVIOURABILITY
B1: Decision Making | C1: Self-Management | D1: Communication | E1: Engagement
A2: TASK 1: Pianificare e gestire il percorso di visita per ottimizzare il tempo | B2: SE, K&S | C2: SE, PC | D2: - | E2: MOT
A3: TASK T2: Comprendere a fondo il patrimonio adattando il livello di dettaglio | B3: SE, K&S | C3: PC | D3: - | E3: MOT
A4: TASK T3: Trasformare la passività in un'esplorazione tematica gratificante | B4: SE, K&S | C4: PC | D4: - | E4: MOT
A15: * cancellare i fattori di abilità che non sono influenzati dalla proprietà comportamentale corrispondente
A16: Legenda
A17: SE = Self-Efficacy
A18: K&S = Knowledge & Skills
A19: PC = Personal Control
A20: MOT = Motivation

Sheet Quest.Utente1
A1: Colonna 1 | B1: Self Efficacy | C1: Scarso | D1: Sufficiente | E1: Buono | F1: Molto Buono | G1: Eccellente | H1: Valore
A2: T1 | B2: Pianificare e gestire il percorso di visita per ottimizzare il tempo
A3: T1_SE1 | B3: Come valuti la tua sicurezza nel riuscire a individuare e raggiungere autonomamente le opere principali del sito pur avendo poco tempo a disposizione? | G3: X | H3: =IF(C3="X",1)+IF(D3="X",2)+IF(E3="X",3)+IF(F3="X",4)+IF(G3="X",5) -> 5
A4: T1_SE2 | B4: Come valuti la tua capacità di orientarti agilmente in un complesso culturale sconosciuto facendoti assistere da indicazioni spaziali in AR? | G4: X | H4: =IF(C4="X",1)+IF(D4="X",2)+IF(E4="X",3)+IF(F4="X",4)+IF(G4="X",5) -> 5
A5: T1_SE3 | B5: Come valuti la tua sicurezza nell'evitare dispersioni logiche durante la visita mantenendo il focus sui punti di maggior pregio? | G5: X | H5: =IF(C5="X",1)+IF(D5="X",2)+IF(E5="X",3)+IF(F5="X",4)+IF(G5="X",5) -> 5
B6: Knowledge&Skills
A7: T1_KS1 | B7: Che livello di conoscenza pregressa possiedi riguardo alla disposizione logistica e ai grandi classici di questo specifico sito culturale? | G7: X | H7: =IF(C7="X",1)+IF(D7="X",2)+IF(E7="X",3)+IF(F7="X",4)+IF(G7="X",5) -> 5
A8: T1_KS2 | B8: Come valuti la tua capacità di organizzare mentalmente un itinerario di visita basato sul tempo reale che hai a disposizione? | G8: X | H8: =IF(C8="X",1)+IF(D8="X",2)+IF(E8="X",3)+IF(F8="X",4)+IF(G8="X",5) -> 5
A9: T1_KS3 | B9: Come valuti la tua capacità di muoverti in siti storici o borghi complessi leggendo l'ambiente circostante? | G9: X | H9: =IF(C9="X",1)+IF(D9="X",2)+IF(E9="X",3)+IF(F9="X",4)+IF(G9="X",5) -> 5
B10: Personal Control
A11: T1_PC1 | B11: Come giudichi la tua capacità di gestire imprevisti spaziali (es. sala chiusa) riorganizzando rapidamente il percorso? | G11: X | H11: =IF(C11="X",1)+IF(D11="X",2)+IF(E11="X",3)+IF(F11="X",4)+IF(G11="X",5) -> 5
A12: T1_PC2 | B12: Pensi di avere il pieno controllo del tuo tempo per assicurarti di vedere tutto ciò che ti eri prefissato prima di dover rincasare? | G12: X | H12: =IF(C12="X",1)+IF(D12="X",2)+IF(E12="X",3)+IF(F12="X",4)+IF(G12="X",5) -> 5
B13: Motivation
A14: T1_MOT1 | B14: Quanto ti senti motivato/a a cercare un aiuto proattivo per massimizzare la resa della tua visita nel poco tempo disponibile? | C14: X | H14: =IF(C14="X",1)+IF(D14="X",2)+IF(E14="X",3)+IF(F14="X",4)+IF(G14="X",5) -> 1
A15: T1_MOT2 | B15: Quanto è importante per te avere un'infarinatura generale e intuitiva subito accessibile per non sentirti spaesato? | C15: X | H15: =IF(C15="X",1)+IF(D15="X",2)+IF(E15="X",3)+IF(F15="X",4)+IF(G15="X",5) -> 1
A16: T1_MOT3 | B16: Quanto ritieni fondamentale il supporto dell'app per abbattere l'ansia di perderti nei corridoi e assicurarti di vedere l'opera principale in tempo? | C16: X | H16: =IF(C16="X",1)+IF(D16="X",2)+IF(E16="X",3)+IF(F16="X",4)+IF(G16="X",5) -> 1
A17: T2 | B17: Comprendere a fondo il patrimonio adattando il livello di dettaglio
A18: T2_SE1 | B18: Come valuti la tua sicurezza nel comprendere il significato di un reperto complesso facendoti supportare da ricostruzioni in Realtà Aumentata? | G18: X | H18: =IF(C18="X",1)+IF(D18="X",2)+IF(E18="X",3)+IF(F18="X",4)+IF(G18="X",5) -> 5
A19: T2_SE2 | B19: Come valuti la tua capacità di interrogare attivamente un'opera tramite l'IA per ottenere risposte a curiosità specifiche o retroscena inediti? | G19: X | H19: =IF(C19="X",1)+IF(D19="X",2)+IF(E19="X",3)+IF(F19="X",4)+IF(G19="X",5) -> 5
A20: T2_SE3 | B20: Come valuti la tua sicurezza nel filtrare dinamicamente i contenuti passando da un livello base a uno accademico senza sentirti frustrato? | G20: X | H20: =IF(C20="X",1)+IF(D20="X",2)+IF(E20="X",3)+IF(F20="X",4)+IF(G20="X",5) -> 5
B21: Knowledge&Skills
A22: T2_KS1 | B22: Che livello di background storico-artistico possiedi per interpretare autonomamente le opere esposte? | G22: X | H22: =IF(C22="X",1)+IF(D22="X",2)+IF(E22="X",3)+IF(F22="X",4)+IF(G22="X",5) -> 5
A23: T2_KS2 | B23: Come valuti la tua abilità nel cogliere i dettagli nascosti o le sfumature di restauro di un'opera d'arte rispetto a una visione d'insieme? | G23: X | H23: =IF(C23="X",1)+IF(D23="X",2)+IF(E23="X",3)+IF(F23="X",4)+IF(G23="X",5) -> 5
A24: T2_KS3 | B24: Come valuti la tua capacità di formulare le domande giuste all'IA per approfondire un argomento culturale che ti incuriosisce? | G24: X | H24: =IF(C24="X",1)+IF(D24="X",2)+IF(E24="X",3)+IF(F24="X",4)+IF(G24="X",5) -> 5
B25: Personal Control
A26: T2_PC1 | B26: Pensi di avere il pieno controllo sulla quantità di informazioni che ricevi potendo decidere quando fermarti per non annoiarti? | G26: X | H26: =IF(C26="X",1)+IF(D26="X",2)+IF(E26="X",3)+IF(F26="X",4)+IF(G26="X",5) -> 5
A27: T2_PC2 | B27: Come giudichi la tua capacità di compensare autonomamente l'assenza di una guida fisica o di un pannello in un piccolo borgo? | G27: X | H27: =IF(C27="X",1)+IF(D27="X",2)+IF(E27="X",3)+IF(F27="X",4)+IF(G27="X",5) -> 5
B28: Motivation
A29: T2_MOT1 | B29: Quanto ti senti motivato/a ad andare oltre la placca ufficiale per scoprire storie occulte o dettagli solitamente ignorati? | G29: X | H29: =IF(C29="X",1)+IF(D29="X",2)+IF(E29="X",3)+IF(F29="X",4)+IF(G29="X",5) -> 5
A30: T2_MOT2 | B30: Quanto è facile per te mantenere vivo l'interesse davanti a un'opera frammentata o decontestualizzata (es. un tempio in rovina)? | G30: X | H30: =IF(C30="X",1)+IF(D30="X",2)+IF(E30="X",3)+IF(F30="X",4)+IF(G30="X",5) -> 5
A31: T2_MOT3 | B31: Quanto ritieni appagante poter accedere tramite l'app a segreti e retroscena non presenti nelle guide cartacee ufficiali per sentirti realmente coinvolto? | G31: X | H31: =IF(C31="X",1)+IF(D31="X",2)+IF(E31="X",3)+IF(F31="X",4)+IF(G31="X",5) -> 5
A32: T3 | B32: Trasformare la passività in un'esplorazione tematica gratificante
A33: T3_SE1 | B33: Come valuti la tua sicurezza nell'affrontare una lunga visita culturale mantenendo un ritmo rilassato senza soccombere alla noia? | G33: X | H33: =IF(C33="X",1)+IF(D33="X",2)+IF(E33="X",3)+IF(F33="X",4)+IF(G33="X",5) -> 5
A34: T3_SE2 | B34: Come valuti la tua capacità di lasciarti guidare fuori dai sentieri battuti seguendo traiettorie tematiche trasversali in app? | G34: X | H34: =IF(C34="X",1)+IF(D34="X",2)+IF(E34="X",3)+IF(F34="X",4)+IF(G34="X",5) -> 5
A35: T3_SE3 | B35: Come valuti la tua capacità di completare con successo le tappe di un'esplorazione per costruire il tuo diario delle visite? | F35: X | H35: =IF(C35="X",1)+IF(D35="X",2)+IF(E35="X",3)+IF(F35="X",4)+IF(G35="X",5) -> 4
B36: Knowledge&Skills
A37: T3_KS1 | B37: Che livello di conoscenza hai delle curiosità locali e degli aneddoti non convenzionali legati alla tua città/territorio? | G37: X | H37: =IF(C37="X",1)+IF(D37="X",2)+IF(E37="X",3)+IF(F37="X",4)+IF(G37="X",5) -> 5
A38: T3_KS2 | B38: Come valuti la tua familiarità con le dinamiche di esplorazione a tappe o gamification (sblocco badge e ricordi multimediali)? | F38: X | H38: =IF(C38="X",1)+IF(D38="X",2)+IF(E38="X",3)+IF(F38="X",4)+IF(G38="X",5) -> 4
A39: T3_KS3 | B39: Come valuti la tua capacità di riconoscere il valore identitario dei luoghi che solitamente vivi solo di sfuggita nella routine? | G39: X | H39: =IF(C39="X",1)+IF(D39="X",2)+IF(E39="X",3)+IF(F39="X",4)+IF(G39="X",5) -> 5
B40: Personal Control
...

Sheet Quest.Utente2
A1: Colonna 1 | B1: Self Efficacy | C1: Scarso | D1: Sufficiente | E1: Buono | F1: Molto Buono | G1: Eccellente | H1: Valore
A2: T1 | B2: Pianificare e gestire il percorso di visita per ottimizzare il tempo
A3: T1_SE1 | B3: Come valuti la tua sicurezza nel riuscire a individuare e raggiungere autonomamente le opere principali del sito pur avendo poco tempo a disposizione? | D3: X | H3: =IF(C3="X",1)+IF(D3="X",2)+IF(E3="X",3)+IF(F3="X",4)+IF(G3="X",5) -> 2
A4: T1_SE2 | B4: Come valuti la tua capacità di orientarti agilmente in un complesso culturale sconosciuto facendoti assistere da indicazioni spaziali in AR? | E4: X | H4: =IF(C4="X",1)+IF(D4="X",2)+IF(E4="X",3)+IF(F4="X",4)+IF(G4="X",5) -> 3
A5: T1_SE3 | B5: Come valuti la tua sicurezza nell'evitare dispersioni logiche durante la visita mantenendo il focus sui punti di maggior pregio? | D5: X | H5: =IF(C5="X",1)+IF(D5="X",2)+IF(E5="X",3)+IF(F5="X",4)+IF(G5="X",5) -> 2
B6: Knowledge&Skills
A7: T1_KS1 | B7: Che livello di conoscenza pregressa possiedi riguardo alla disposizione logistica e ai grandi classici di questo specifico sito culturale? | C7: X | H7: =IF(C7="X",1)+IF(D7="X",2)+IF(E7="X",3)+IF(F7="X",4)+IF(G7="X",5) -> 1
A8: T1_KS2 | B8: Come valuti la tua capacità di organizzare mentalmente un itinerario di visita basato sul tempo reale che hai a disposizione? | D8: X | H8: =IF(C8="X",1)+IF(D8="X",2)+IF(E8="X",3)+IF(F8="X",4)+IF(G8="X",5) -> 2
A9: T1_KS3 | B9: Come valuti la tua capacità di muoverti in siti storici o borghi complessi leggendo l'ambiente circostante? | E9: X | H9: =IF(C9="X",1)+IF(D9="X",2)+IF(E9="X",3)+IF(F9="X",4)+IF(G9="X",5) -> 3
B10: Personal Control
A11: T1_PC1 | B11: Come giudichi la tua capacità di gestire imprevisti spaziali (es. sala chiusa) riorganizzando rapidamente il percorso? | D11: X | H11: =IF(C11="X",1)+IF(D11="X",2)+IF(E11="X",3)+IF(F11="X",4)+IF(G11="X",5) -> 2
A12: T1_PC2 | B12: Pensi di avere il pieno controllo del tuo tempo per assicurarti di vedere tutto ciò che ti eri prefissato prima di dover rincasare? | D12: X | H12: =IF(C12="X",1)+IF(D12="X",2)+IF(E12="X",3)+IF(F12="X",4)+IF(G12="X",5) -> 2
B13: Motivation
A14: T1_MOT1 | B14: Quanto ti senti motivato/a a cercare un aiuto proattivo per massimizzare la resa della tua visita nel poco tempo disponibile? | G14: X | H14: =IF(C14="X",1)+IF(D14="X",2)+IF(E14="X",3)+IF(F14="X",4)+IF(G14="X",5) -> 5
A15: T1_MOT2 | B15: Quanto è importante per te avere un'infarinatura generale e intuitiva subito accessibile per non sentirti spaesato? | G15: X | H15: =IF(C15="X",1)+IF(D15="X",2)+IF(E15="X",3)+IF(F15="X",4)+IF(G15="X",5) -> 5
A16: T1_MOT3 | B16: Quanto ritieni fondamentale il supporto dell'app per abbattere l'ansia di perderti nei corridoi e assicurarti di vedere l'opera principale in tempo? | G16: X | H16: =IF(C16="X",1)+IF(D16="X",2)+IF(E16="X",3)+IF(F16="X",4)+IF(G16="X",5) -> 5
A17: T2 | B17: Comprendere a fondo il patrimonio adattando il livello di dettaglio
A18: T2_SE1 | B18: Come valuti la tua sicurezza nel comprendere il significato di un reperto complesso facendoti supportare da ricostruzioni in Realtà Aumentata? | E18: X | H18: =IF(C18="X",1)+IF(D18="X",2)+IF(E18="X",3)+IF(F18="X",4)+IF(G18="X",5) -> 3
A19: T2_SE2 | B19: Come valuti la tua capacità di interrogare attivamente un'opera tramite l'IA per ottenere risposte a curiosità specifiche o retroscena inediti? | D19: X | H19: =IF(C19="X",1)+IF(D19="X",2)+IF(E19="X",3)+IF(F19="X",4)+IF(G19="X",5) -> 2
A20: T2_SE3 | B20: Come valuti la tua sicurezza nel filtrare dinamicamente i contenuti passando da un livello base a uno accademico senza sentirti frustrato? | D20: X | H20: =IF(C20="X",1)+IF(D20="X",2)+IF(E20="X",3)+IF(F20="X",4)+IF(G20="X",5) -> 2
B21: Knowledge&Skills
A22: T2_KS1 | B22: Che livello di background storico-artistico possiedi per interpretare autonomamente le opere esposte? | D22: X | H22: =IF(C22="X",1)+IF(D22="X",2)+IF(E22="X",3)+IF(F22="X",4)+IF(G22="X",5) -> 2
A23: T2_KS2 | B23: Come valuti la tua abilità nel cogliere i dettagli nascosti o le sfumature di restauro di un'opera d'arte rispetto a una visione d'insieme? | D23: X | H23: =IF(C23="X",1)+IF(D23="X",2)+IF(E23="X",3)+IF(F23="X",4)+IF(G23="X",5) -> 2
A24: T2_KS3 | B24: Come valuti la tua capacità di formulare le domande giuste all'IA per approfondire un argomento culturale che ti incuriosisce? | D24: X | H24: =IF(C24="X",1)+IF(D24="X",2)+IF(E24="X",3)+IF(F24="X",4)+IF(G24="X",5) -> 2
B25: Personal Control
A26: T2_PC1 | B26: Pensi di avere il pieno controllo sulla quantità di informazioni che ricevi potendo decidere quando fermarti per non annoiarti? | F26: X | H26: =IF(C26="X",1)+IF(D26="X",2)+IF(E26="X",3)+IF(F26="X",4)+IF(G26="X",5) -> 4
A27: T2_PC2 | B27: Come giudichi la tua capacità di compensare autonomamente l'assenza di una guida fisica o di un pannello in un piccolo borgo? | D27: X | H27: =IF(C27="X",1)+IF(D27="X",2)+IF(E27="X",3)+IF(F27="X",4)+IF(G27="X",5) -> 2
B28: Motivation
A29: T2_MOT1 | B29: Quanto ti senti motivato/a ad andare oltre la placca ufficiale per scoprire storie occulte o dettagli solitamente ignorati? | C29: X | H29: =IF(C29="X",1)+IF(D29="X",2)+IF(E29="X",3)+IF(F29="X",4)+IF(G29="X",5) -> 1
A30: T2_MOT2 | B30: Quanto è facile per te mantenere vivo l'interesse davanti a un'opera frammentata o decontestualizzata (es. un tempio in rovina)? | D30: X | H30: =IF(C30="X",1)+IF(D30="X",2)+IF(E30="X",3)+IF(F30="X",4)+IF(G30="X",5) -> 2
A31: T2_MOT3 | B31: Quanto ritieni appagante poter accedere tramite l'app a segreti e retroscena non presenti nelle guide cartacee ufficiali per sentirti realmente coinvolto? | D31: X | H31: =IF(C31="X",1)+IF(D31="X",2)+IF(E31="X",3)+IF(F31="X",4)+IF(G31="X",5) -> 2
A32: T3 | B32: Trasformare la passività in un'esplorazione tematica gratificante
A33: T3_SE1 | B33: Come valuti la tua sicurezza nell'affrontare una lunga visita culturale mantenendo un ritmo rilassato senza soccombere alla noia? | C33: X | H33: =IF(C33="X",1)+IF(D33="X",2)+IF(E33="X",3)+IF(F33="X",4)+IF(G33="X",5) -> 1
A34: T3_SE2 | B34: Come valuti la tua capacità di lasciarti guidare fuori dai sentieri battuti seguendo traiettorie tematiche trasversali in app? | C34: X | H34: =IF(C34="X",1)+IF(D34="X",2)+IF(E34="X",3)+IF(F34="X",4)+IF(G34="X",5) -> 1
A35: T3_SE3 | B35: Come valuti la tua capacità di completare con successo le tappe di un'esplorazione per costruire il tuo diario delle visite? | C35: X | H35: =IF(C35="X",1)+IF(D35="X",2)+IF(E35="X",3)+IF(F35="X",4)+IF(G35="X",5) -> 1
B36: Knowledge&Skills
A37: T3_KS1 | B37: Che livello di conoscenza hai delle curiosità locali e degli aneddoti non convenzionali legati alla tua città/territorio? | C37: X | H37: =IF(C37="X",1)+IF(D37="X",2)+IF(E37="X",3)+IF(F37="X",4)+IF(G37="X",5) -> 1
A38: T3_KS2 | B38: Come valuti la tua familiarità con le dinamiche di esplorazione a tappe o gamification (sblocco badge e ricordi multimediali)? | D38: X | H38: =IF(C38="X",1)+IF(D38="X",2)+IF(E38="X",3)+IF(F38="X",4)+IF(G38="X",5) -> 2
A39: T3_KS3 | B39: Come valuti la tua capacità di riconoscere il valore identitario dei luoghi che solitamente vivi solo di sfuggita nella routine? | D39: X | H39: =IF(C39="X",1)+IF(D39="X",2)+IF(E39="X",3)+IF(F39="X",4)+IF(G39="X",5) -> 2
B40: Personal Control
...

Sheet Quest.Utente3
A1: Colonna 1 | B1: Self Efficacy | C1: Scarso | D1: Sufficiente | E1: Buono | F1: Molto Buono | G1: Eccellente | H1: Valore
A2: T1 | B2: Pianificare e gestire il percorso di visita per ottimizzare il tempo
A3: T1_SE1 | B3: Come valuti la tua sicurezza nel riuscire a individuare e raggiungere autonomamente le opere principali del sito pur avendo poco tempo a disposizione? | E3: X | H3: =IF(C3="X",1)+IF(D3="X",2)+IF(E3="X",3)+IF(F3="X",4)+IF(G3="X",5) -> 3
A4: T1_SE2 | B4: Come valuti la tua capacità di orientarti agilmente in un complesso culturale sconosciuto facendoti assistere da indicazioni spaziali in AR? | F4: X | H4: =IF(C4="X",1)+IF(D4="X",2)+IF(E4="X",3)+IF(F4="X",4)+IF(G4="X",5) -> 4
A5: T1_SE3 | B5: Come valuti la tua sicurezza nell'evitare dispersioni logiche durante la visita mantenendo il focus sui punti di maggior pregio? | E5: X | H5: =IF(C5="X",1)+IF(D5="X",2)+IF(E5="X",3)+IF(F5="X",4)+IF(G5="X",5) -> 3
B6: Knowledge&Skills
A7: T1_KS1 | B7: Che livello di conoscenza pregressa possiedi riguardo alla disposizione logistica e ai grandi classici di questo specifico sito culturale? | D7: X | H7: =IF(C7="X",1)+IF(D7="X",2)+IF(E7="X",3)+IF(F7="X",4)+IF(G7="X",5) -> 2
A8: T1_KS2 | B8: Come valuti la tua capacità di organizzare mentalmente un itinerario di visita basato sul tempo reale che hai a disposizione? | F8: X | H8: =IF(C8="X",1)+IF(D8="X",2)+IF(E8="X",3)+IF(F8="X",4)+IF(G8="X",5) -> 4
A9: T1_KS3 | B9: Come valuti la tua capacità di muoverti in siti storici o borghi complessi leggendo l'ambiente circostante? | D9: X | H9: =IF(C9="X",1)+IF(D9="X",2)+IF(E9="X",3)+IF(F9="X",4)+IF(G9="X",5) -> 2
B10: Personal Control
A11: T1_PC1 | B11: Come giudichi la tua capacità di gestire imprevisti spaziali (es. sala chiusa) riorganizzando rapidamente il percorso? | F11: X | H11: =IF(C11="X",1)+IF(D11="X",2)+IF(E11="X",3)+IF(F11="X",4)+IF(G11="X",5) -> 4
A12: T1_PC2 | B12: Pensi di avere il pieno controllo del tuo tempo per assicurarti di vedere tutto ciò che ti eri prefissato prima di dover rincasare? | G12: X | H12: =IF(C12="X",1)+IF(D12="X",2)+IF(E12="X",3)+IF(F12="X",4)+IF(G12="X",5) -> 5
B13: Motivation
A14: T1_MOT1 | B14: Quanto ti senti motivato/a a cercare un aiuto proattivo per massimizzare la resa della tua visita nel poco tempo disponibile? | F14: X | H14: =IF(C14="X",1)+IF(D14="X",2)+IF(E14="X",3)+IF(F14="X",4)+IF(G14="X",5) -> 4
A15: T1_MOT2 | B15: Quanto è importante per te avere un'infarinatura generale e intuitiva subito accessibile per non sentirti spaesato? | G15: X | H15: =IF(C15="X",1)+IF(D15="X",2)+IF(E15="X",3)+IF(F15="X",4)+IF(G15="X",5) -> 5
A16: T1_MOT3 | B16: Quanto ritieni fondamentale il supporto dell'app per abbattere l'ansia di perderti nei corridoi e assicurarti di vedere l'opera principale in tempo? | G16: X | H16: =IF(C16="X",1)+IF(D16="X",2)+IF(E16="X",3)+IF(F16="X",4)+IF(G16="X",5) -> 5
A17: T2 | B17: Comprendere a fondo il patrimonio adattando il livello di dettaglio
A18: T2_SE1 | B18: Come valuti la tua sicurezza nel comprendere il significato di un reperto complesso facendoti supportare da ricostruzioni in Realtà Aumentata? | F18: X | H18: =IF(C18="X",1)+IF(D18="X",2)+IF(E18="X",3)+IF(F18="X",4)+IF(G18="X",5) -> 4
A19: T2_SE2 | B19: Come valuti la tua capacità di interrogare attivamente un'opera tramite l'IA per ottenere risposte a curiosità specifiche o retroscena inediti? | E19: X | H19: =IF(C19="X",1)+IF(D19="X",2)+IF(E19="X",3)+IF(F19="X",4)+IF(G19="X",5) -> 3
A20: T2_SE3 | B20: Come valuti la tua sicurezza nel filtrare dinamicamente i contenuti passando da un livello base a uno accademico senza sentirti frustrato? | D20: X | H20: =IF(C20="X",1)+IF(D20="X",2)+IF(E20="X",3)+IF(F20="X",4)+IF(G20="X",5) -> 2
B21: Knowledge&Skills
A22: T2_KS1 | B22: Che livello di background storico-artistico possiedi per interpretare autonomamente le opere esposte? | D22: X | H22: =IF(C22="X",1)+IF(D22="X",2)+IF(E22="X",3)+IF(F22="X",4)+IF(G22="X",5) -> 2
A23: T2_KS2 | B23: Come valuti la tua abilità nel cogliere i dettagli nascosti o le sfumature di restauro di un'opera d'arte rispetto a una visione d'insieme? | E23: X | H23: =IF(C23="X",1)+IF(D23="X",2)+IF(E23="X",3)+IF(F23="X",4)+IF(G23="X",5) -> 3
A24: T2_KS3 | B24: Come valuti la tua capacità di formulare le domande giuste all'IA per approfondire un argomento culturale che ti incuriosisce? | E24: X | H24: =IF(C24="X",1)+IF(D24="X",2)+IF(E24="X",3)+IF(F24="X",4)+IF(G24="X",5) -> 3
B25: Personal Control
A26: T2_PC1 | B26: Pensi di avere il pieno controllo sulla quantità di informazioni che ricevi potendo decidere quando fermarti per non annoiarti? | F26: X | H26: =IF(C26="X",1)+IF(D26="X",2)+IF(E26="X",3)+IF(F26="X",4)+IF(G26="X",5) -> 4
A27: T2_PC2 | B27: Come giudichi la tua capacità di compensare autonomamente l'assenza di una guida fisica o di un pannello in un piccolo borgo? | D27: X | H27: =IF(C27="X",1)+IF(D27="X",2)+IF(E27="X",3)+IF(F27="X",4)+IF(G27="X",5) -> 2
B28: Motivation
A29: T2_MOT1 | B29: Quanto ti senti motivato/a ad andare oltre la placca ufficiale per scoprire storie occulte o dettagli solitamente ignorati? | F29: X | H29: =IF(C29="X",1)+IF(D29="X",2)+IF(E29="X",3)+IF(F29="X",4)+IF(G29="X",5) -> 4
A30: T2_MOT2 | B30: Quanto è facile per te mantenere vivo l'interesse davanti a un'opera frammentata o decontestualizzata (es. un tempio in rovina)? | E30: X | H30: =IF(C30="X",1)+IF(D30="X",2)+IF(E30="X",3)+IF(F30="X",4)+IF(G30="X",5) -> 3
A31: T2_MOT3 | B31: Quanto ritieni appagante poter accedere tramite l'app a segreti e retroscena non presenti nelle guide cartacee ufficiali per sentirti realmente coinvolto? | G31: X | H31: =IF(C31="X",1)+IF(D31="X",2)+IF(E31="X",3)+IF(F31="X",4)+IF(G31="X",5) -> 5
A32: T3 | B32: Trasformare la passività in un'esplorazione tematica gratificante
A33: T3_SE1 | B33: Come valuti la tua sicurezza nell'affrontare una lunga visita culturale mantenendo un ritmo rilassato senza soccombere alla noia? | G33: X | H33: =IF(C33="X",1)+IF(D33="X",2)+IF(E33="X",3)+IF(F33="X",4)+IF(G33="X",5) -> 5
A34: T3_SE2 | B34: Come valuti la tua capacità di lasciarti guidare fuori dai sentieri battuti seguendo traiettorie tematiche trasversali in app? | F34: X | H34: =IF(C34="X",1)+IF(D34="X",2)+IF(E34="X",3)+IF(F34="X",4)+IF(G34="X",5) -> 4
A35: T3_SE3 | B35: Come valuti la tua capacità di completare con successo le tappe di un'esplorazione per costruire il tuo diario delle visite? | D35: X | H35: =IF(C35="X",1)+IF(D35="X",2)+IF(E35="X",3)+IF(F35="X",4)+IF(G35="X",5) -> 2
B36: Knowledge&Skills
A37: T3_KS1 | B37: Che livello di conoscenza hai delle curiosità locali e degli aneddoti non convenzionali legati alla tua città/territorio? | E37: X | H37: =IF(C37="X",1)+IF(D37="X",2)+IF(E37="X",3)+IF(F37="X",4)+IF(G37="X",5) -> 3
A38: T3_KS2 | B38: Come valuti la tua familiarità con le dinamiche di esplorazione a tappe o gamification (sblocco badge e ricordi multimediali)? | F38: X | H38: =IF(C38="X",1)+IF(D38="X",2)+IF(E38="X",3)+IF(F38="X",4)+IF(G38="X",5) -> 4
A39: T3_KS3 | B39: Come valuti la tua capacità di riconoscere il valore identitario dei luoghi che solitamente vivi solo di sfuggita nella routine? | D39: X | H39: =IF(C39="X",1)+IF(D39="X",2)+IF(E39="X",3)+IF(F39="X",4)+IF(G39="X",5) -> 2
B40: Personal Control
...

Sheet Quest.Utente4
A1: Colonna 1 | B1: Self Efficacy | C1: Scarso | D1: Sufficiente | E1: Buono | F1: Molto Buono | G1: Eccellente | H1: Valore
A2: T1 | B2: Pianificare e gestire il percorso di visita per ottimizzare il tempo
A3: T1_SE1 | B3: Come valuti la tua sicurezza nel riuscire a individuare e raggiungere autonomamente le opere principali del sito pur avendo poco tempo a disposizione? | G3: X | H3: =IF(C3="X",1)+IF(D3="X",2)+IF(E3="X",3)+IF(F3="X",4)+IF(G3="X",5) -> 5
A4: T1_SE2 | B4: Come valuti la tua capacità di orientarti agilmente in un complesso culturale sconosciuto facendoti assistere da indicazioni spaziali in AR? | E4: X | H4: =IF(C4="X",1)+IF(D4="X",2)+IF(E4="X",3)+IF(F4="X",4)+IF(G4="X",5) -> 3
A5: T1_SE3 | B5: Come valuti la tua sicurezza nell'evitare dispersioni logiche durante la visita mantenendo il focus sui punti di maggior pregio? | G5: X | H5: =IF(C5="X",1)+IF(D5="X",2)+IF(E5="X",3)+IF(F5="X",4)+IF(G5="X",5) -> 5
B6: Knowledge&Skills
A7: T1_KS1 | B7: Che livello di conoscenza pregressa possiedi riguardo alla disposizione logistica e ai grandi classici di questo specifico sito culturale? | G7: X | H7: =IF(C7="X",1)+IF(D7="X",2)+IF(E7="X",3)+IF(F7="X",4)+IF(G7="X",5) -> 5
A8: T1_KS2 | B8: Come valuti la tua capacità di organizzare mentalmente un itinerario di visita basato sul tempo reale che hai a disposizione? | G8: X | H8: =IF(C8="X",1)+IF(D8="X",2)+IF(E8="X",3)+IF(F8="X",4)+IF(G8="X",5) -> 5
A9: T1_KS3 | B9: Come valuti la tua capacità di muoverti in siti storici o borghi complessi leggendo l'ambiente circostante? | G9: X | H9: =IF(C9="X",1)+IF(D9="X",2)+IF(E9="X",3)+IF(F9="X",4)+IF(G9="X",5) -> 5
B10: Personal Control
A11: T1_PC1 | B11: Come giudichi la tua capacità di gestire imprevisti spaziali (es. sala chiusa) riorganizzando rapidamente il percorso? | G11: X | H11: =IF(C11="X",1)+IF(D11="X",2)+IF(E11="X",3)+IF(F11="X",4)+IF(G11="X",5) -> 5
A12: T1_PC2 | B12: Pensi di avere il pieno controllo del tuo tempo per assicurarti di vedere tutto ciò che ti eri prefissato prima di dover rincasare? | F12: X | H12: =IF(C12="X",1)+IF(D12="X",2)+IF(E12="X",3)+IF(F12="X",4)+IF(G12="X",5) -> 4
B13: Motivation
A14: T1_MOT1 | B14: Quanto ti senti motivato/a a cercare un aiuto proattivo per massimizzare la resa della tua visita nel poco tempo disponibile? | F14: X | H14: =IF(C14="X",1)+IF(D14="X",2)+IF(E14="X",3)+IF(F14="X",4)+IF(G14="X",5) -> 4
A15: T1_MOT2 | B15: Quanto è importante per te avere un'infarinatura generale e intuitiva subito accessibile per non sentirti spaesato? | D15: X | H15: =IF(C15="X",1)+IF(D15="X",2)+IF(E15="X",3)+IF(F15="X",4)+IF(G15="X",5) -> 2
A16: T1_MOT3 | B16: Quanto ritieni fondamentale il supporto dell'app per abbattere l'ansia di perderti nei corridoi e assicurarti di vedere l'opera principale in tempo? | E16: X | H16: =IF(C16="X",1)+IF(D16="X",2)+IF(E16="X",3)+IF(F16="X",4)+IF(G16="X",5) -> 3
A17: T2 | B17: Comprendere a fondo il patrimonio adattando il livello di dettaglio
A18: T2_SE1 | B18: Come valuti la tua sicurezza nel comprendere il significato di un reperto complesso facendoti supportare da ricostruzioni in Realtà Aumentata? | F18: X | H18: =IF(C18="X",1)+IF(D18="X",2)+IF(E18="X",3)+IF(F18="X",4)+IF(G18="X",5) -> 4
A19: T2_SE2 | B19: Come valuti la tua capacità di interrogare attivamente un'opera tramite l'IA per ottenere risposte a curiosità specifiche o retroscena inediti? | F19: X | H19: =IF(C19="X",1)+IF(D19="X",2)+IF(E19="X",3)+IF(F19="X",4)+IF(G19="X",5) -> 4
A20: T2_SE3 | B20: Come valuti la tua sicurezza nel filtrare dinamicamente i contenuti passando da un livello base a uno accademico senza sentirti frustrato? | G20: X | H20: =IF(C20="X",1)+IF(D20="X",2)+IF(E20="X",3)+IF(F20="X",4)+IF(G20="X",5) -> 5
B21: Knowledge&Skills
A22: T2_KS1 | B22: Che livello di background storico-artistico possiedi per interpretare autonomamente le opere esposte? | F22: X | H22: =IF(C22="X",1)+IF(D22="X",2)+IF(E22="X",3)+IF(F22="X",4)+IF(G22="X",5) -> 4
A23: T2_KS2 | B23: Come valuti la tua abilità nel cogliere i dettagli nascosti o le sfumature di restauro di un'opera d'arte rispetto a una visione d'insieme? | G23: X | H23: =IF(C23="X",1)+IF(D23="X",2)+IF(E23="X",3)+IF(F23="X",4)+IF(G23="X",5) -> 5
A24: T2_KS3 | B24: Come valuti la tua capacità di formulare le domande giuste all'IA per approfondire un argomento culturale che ti incuriosisce? | F24: X | H24: =IF(C24="X",1)+IF(D24="X",2)+IF(E24="X",3)+IF(F24="X",4)+IF(G24="X",5) -> 4
B25: Personal Control
A26: T2_PC1 | B26: Pensi di avere il pieno controllo sulla quantità di informazioni che ricevi potendo decidere quando fermarti per non annoiarti? | D26: X | H26: =IF(C26="X",1)+IF(D26="X",2)+IF(E26="X",3)+IF(F26="X",4)+IF(G26="X",5) -> 2
A27: T2_PC2 | B27: Come giudichi la tua capacità di compensare autonomamente l'assenza di una guida fisica o di un pannello in un piccolo borgo? | G27: X | H27: =IF(C27="X",1)+IF(D27="X",2)+IF(E27="X",3)+IF(F27="X",4)+IF(G27="X",5) -> 5
B28: Motivation
A29: T2_MOT1 | B29: Quanto ti senti motivato/a ad andare oltre la placca ufficiale per scoprire storie occulte o dettagli solitamente ignorati? | F29: X | H29: =IF(C29="X",1)+IF(D29="X",2)+IF(E29="X",3)+IF(F29="X",4)+IF(G29="X",5) -> 4
A30: T2_MOT2 | B30: Quanto è facile per te mantenere vivo l'interesse davanti a un'opera frammentata o decontestualizzata (es. un tempio in rovina)? | G30: X | H30: =IF(C30="X",1)+IF(D30="X",2)+IF(E30="X",3)+IF(F30="X",4)+IF(G30="X",5) -> 5
A31: T2_MOT3 | B31: Quanto ritieni appagante poter accedere tramite l'app a segreti e retroscena non presenti nelle guide cartacee ufficiali per sentirti realmente coinvolto? | D31: X | H31: =IF(C31="X",1)+IF(D31="X",2)+IF(E31="X",3)+IF(F31="X",4)+IF(G31="X",5) -> 2
A32: T3 | B32: Trasformare la passività in un'esplorazione tematica gratificante
A33: T3_SE1 | B33: Come valuti la tua sicurezza nell'affrontare una lunga visita culturale mantenendo un ritmo rilassato senza soccombere alla noia? | G33: X | H33: =IF(C33="X",1)+IF(D33="X",2)+IF(E33="X",3)+IF(F33="X",4)+IF(G33="X",5) -> 5
A34: T3_SE2 | B34: Come valuti la tua capacità di lasciarti guidare fuori dai sentieri battuti seguendo traiettorie tematiche trasversali in app? | F34: X | H34: =IF(C34="X",1)+IF(D34="X",2)+IF(E34="X",3)+IF(F34="X",4)+IF(G34="X",5) -> 4
A35: T3_SE3 | B35: Come valuti la tua capacità di completare con successo le tappe di un'esplorazione per costruire il tuo diario delle visite? | D35: X | H35: =IF(C35="X",1)+IF(D35="X",2)+IF(E35="X",3)+IF(F35="X",4)+IF(G35="X",5) -> 2
B36: Knowledge&Skills
A37: T3_KS1 | B37: Che livello di conoscenza hai delle curiosità locali e degli aneddoti non convenzionali legati alla tua città/territorio? | G37: X | H37: =IF(C37="X",1)+IF(D37="X",2)+IF(E37="X",3)+IF(F37="X",4)+IF(G37="X",5) -> 5
A38: T3_KS2 | B38: Come valuti la tua familiarità con le dinamiche di esplorazione a tappe o gamification (sblocco badge e ricordi multimediali)? | D38: X | H38: =IF(C38="X",1)+IF(D38="X",2)+IF(E38="X",3)+IF(F38="X",4)+IF(G38="X",5) -> 2
A39: T3_KS3 | B39: Come valuti la tua capacità di riconoscere il valore identitario dei luoghi che solitamente vivi solo di sfuggita nella routine? | G39: X | H39: =IF(C39="X",1)+IF(D39="X",2)+IF(E39="X",3)+IF(F39="X",4)+IF(G39="X",5) -> 5
B40: Personal Control
...

Sheet MEDIE
C1: Scarso | D1: Sufficiente | E1: Buono | F1: Molto Buono | G1: Eccellente | H1: Valore
A2: T1 | B2: Cercare e scegliere un hotel a Venezia
A3: T1_SE1 | B3: Come valuti la tua sicurezza nel scegliere un hotel adatto alle tue esigenze utilizzando un'app di prenotazione? | H3: =AVERAGE(Quest.Utente1!H3,Quest.Utente2!H3,Quest.Utente3!H3,Quest.Utente4!H3) -> 3.75 | I3: MEDIA DELLE RISPOSTE | J3: Self Efficacy
A4: T1_SE2 | B4: Come valuti la tua capacità di confrontare diverse opzioni di hotel (prezzo, posizione, recensioni) in modo efficace? | H4: =AVERAGE(Quest.Utente1!H4,Quest.Utente2!H4,Quest.Utente3!H4,Quest.Utente4!H4) -> 3.75 | I4: MEDIA DELLE RISPOSTE
A5: T1_SE3 | B5: Come valuti il supporto che ricevi dagli strumenti digitali (filtri, mappe, recensioni) per scegliere un hotel? | H5: =AVERAGE(Quest.Utente1!H5,Quest.Utente2!H5,Quest.Utente3!H5,Quest.Utente4!H5) -> 3.75 | I5: MEDIA DELLE RISPOSTE
H6: =AVERAGE(H3:H5) -> 3.75 | I6: MEDIA TRA I VALORI MEDI RELATIVI A QUELL'ABILITA' | J6: Self Efficacy
A7: T1_KS1 | B7: Che livello di conoscenza hai delle zone e dei quartieri di Venezia per scegliere la posizione dell'hotel? | H7: =AVERAGE(Quest.Utente1!H7,Quest.Utente2!H7,Quest.Utente3!H7,Quest.Utente4!H7) -> 3.25
A8: T1_KS2 | B8: Come valuti la tua competenza nell'uso di app di prenotazione alberghiera (Booking, Expedia, ecc.)? | H8: =AVERAGE(Quest.Utente1!H8,Quest.Utente2!H8,Quest.Utente3!H8,Quest.Utente4!H8) -> 4
A9: T1_KS3 | B9: Come valuti la tua capacità di interpretare correttamente le informazioni di un annuncio (politiche di cancellazione, servizi inclusi, ecc.)? | H9: =AVERAGE(Quest.Utente1!H9,Quest.Utente2!H9,Quest.Utente3!H9,Quest.Utente4!H9) -> 3.75
H10: =AVERAGE(H7:H9) -> 3.6666667 | J10: Knowledge&Skills
A11: T1_PC1 | B11: Come giudichi la tua capacità di gestire imprevisti durante la prenotazione (es. hotel non disponibile, cambio di date)? | H11: =AVERAGE(Quest.Utente1!H11,Quest.Utente2!H11,Quest.Utente3!H11,Quest.Utente4!H11) -> 4
A12: T1_PC2 | B12: Pensi di avere il pieno controllo del processo di ricerca e prenotazione di un hotel? | H12: =AVERAGE(Quest.Utente1!H12,Quest.Utente2!H12,Quest.Utente3!H12,Quest.Utente4!H12) -> 4
H13: =AVERAGE(H11:H12) -> 4 | J13: Personal Control
A14: T1_MOT1 | B14: Quanto è facile per te dedicare il tempo necessario a cercare l'hotel migliore? | H14: =AVERAGE(Quest.Utente1!H14,Quest.Utente2!H14,Quest.Utente3!H14,Quest.Utente4!H14) -> 3.5
A15: T1_MOT2 | B15: Quanto ti senti motivato/a a esplorare più opzioni prima di prendere una decisione? | H15: =AVERAGE(Quest.Utente1!H15,Quest.Utente2!H15,Quest.Utente3!H15,Quest.Utente4!H15) -> 3.25
A16: T1_MOT3 | B16: Descrivi le tue preoccupazioni, aspettative e il valore che attribuisci a questo task | H16: =AVERAGE(Quest.Utente1!H16,Quest.Utente2!H16,Quest.Utente3!H16,Quest.Utente4!H16) -> 3.5
H17: =AVERAGE(H14:H16) -> 3.4166667 | J17: Motivation
A18: T2 | B18: Prenotare un mezzo di trasporto per raggiungere Venezia
A19: T2_SE1 | B19: Come valuti la tua sicurezza nello scegliere il mezzo di trasporto più adatto (treno, aereo, autobus, auto) per raggiungere Venezia? | H19: =AVERAGE(Quest.Utente1!H18,Quest.Utente2!H18,Quest.Utente3!H18,Quest.Utente4!H18) -> 4 | I19: MEDIA DELLE RISPOSTE | J19: Self Efficacy
A20: T2_SE2 | B20: Come valuti la tua capacità di completare una prenotazione di trasporto online in autonomia? | H20: =AVERAGE(Quest.Utente1!H19,Quest.Utente2!H19,Quest.Utente3!H19,Quest.Utente4!H19) -> 3.5 | I20: MEDIA DELLE RISPOSTE
A21: T2_SE3 | B21: Come valuti la tua capacità di confrontare prezzi, orari e durata del viaggio tra diverse opzioni di trasporto? | H21: =AVERAGE(Quest.Utente1!H20,Quest.Utente2!H20,Quest.Utente3!H20,Quest.Utente4!H20) -> 3.5 | I21: MEDIA DELLE RISPOSTE
H22: =AVERAGE(H19:H21) -> 3.6666667 | I22: MEDIA TRA I VALORI MEDI RELATIVI A QUELL'ABILITA' | J22: Self Efficacy
A23: T2_KS1 | B23: Che livello di conoscenza hai delle diverse modalità di trasporto disponibili per raggiungere Venezia dalla tua città? | H23: =AVERAGE(Quest.Utente1!H22,Quest.Utente2!H22,Quest.Utente3!H22,Quest.Utente4!H22) -> 3.25
A24: T2_KS2 | B24: Come valuti la tua competenza nell'uso di piattaforme di prenotazione trasporti (Omio, Trenitalia, Flixbus, ecc.)? | H24: =AVERAGE(Quest.Utente1!H23,Quest.Utente2!H23,Quest.Utente3!H23,Quest.Utente4!H23) -> 3.75
A25: T2_KS3 | B25: Come valuti la tua comprensione delle condizioni di viaggio (bagagli, cambi, rimborsi)? | H25: =AVERAGE(Quest.Utente1!H24,Quest.Utente2!H24,Quest.Utente3!H24,Quest.Utente4!H24) -> 3.5
H26: =AVERAGE(H23:H25) -> 3.5 | J26: Knowledge&Skills
A27: T2_PC1 | B27: Come giudichi la tua capacità di gestire imprevisti legati al trasporto (es. ritardi, cancellazioni, cambio di itinerario)? | H27: =AVERAGE(Quest.Utente1!H26,Quest.Utente2!H26,Quest.Utente3!H26,Quest.Utente4!H26) -> 3.75
A28: T2_PC2 | B28: Pensi di avere il controllo del processo di prenotazione del trasporto? | H28: =AVERAGE(Quest.Utente1!H27,Quest.Utente2!H27,Quest.Utente3!H27,Quest.Utente4!H27) -> 3.5
H29: =AVERAGE(H27:H28) -> 3.625 | J29: Personal Control
A30: T2_MOT1 | B30: Quanto è facile per te organizzare la parte del trasporto del viaggio? | H30: =AVERAGE(Quest.Utente1!H29,Quest.Utente2!H29,Quest.Utente3!H29,Quest.Utente4!H29) -> 3.5
A31: T2_MOT2 | B31: Quanto ti senti motivato/a a cercare la soluzione di trasporto ottimale (miglior rapporto qualità-prezzo)? | H31: =AVERAGE(Quest.Utente1!H30,Quest.Utente2!H30,Quest.Utente3!H30,Quest.Utente4!H30) -> 3.75
A32: T2_MOT3 | B32: Descrivi le tue preoccupazioni, aspettative e il valore che attribuisci a questo task | H32: =AVERAGE(Quest.Utente1!H31,Quest.Utente2!H31,Quest.Utente3!H31,Quest.Utente4!H31) -> 3.5
H33: =AVERAGE(H30:H32) -> 3.5833333 | J33: Motivation
A34: T3 | B34: Pianificare un'attività da fare a Venezia
A35: T3_SE1 | B35: Come valuti la tua sicurezza nel pianificare attività da fare a Venezia (visite, escursioni, esperienze)? | H35: =AVERAGE(Quest.Utente1!H33,Quest.Utente2!H33,Quest.Utente3!H33,Quest.Utente4!H33) -> 4 | I35: MEDIA DELLE RISPOSTE | J35: Self Efficacy
A36: T3_SE2 | B36: Come valuti la tua capacità di organizzare un programma giornaliero di attività in modo realistico? | H36: =AVERAGE(Quest.Utente1!H34,Quest.Utente2!H34,Quest.Utente3!H34,Quest.Utente4!H34) -> 3.5 | I36: MEDIA DELLE RISPOSTE
A37: T3_SE3 | B37: Come valuti la tua capacità di trovare e prenotare attività ed esperienze tramite app o siti web? | H37: =AVERAGE(Quest.Utente1!H35,Quest.Utente2!H35,Quest.Utente3!H35,Quest.Utente4!H35) -> 2.25 | I37: MEDIA DELLE RISPOSTE
H38: =AVERAGE(H35:H37) -> 3.25 | I38: MEDIA TRA I VALORI MEDI RELATIVI A QUELL'ABILITA' | J38: Self Efficacy
A39: T3_KS1 | B39: Che livello di conoscenza hai delle attrazioni e delle attività disponibili a Venezia? | H39: =AVERAGE(Quest.Utente1!H37,Quest.Utente2!H37,Quest.Utente3!H37,Quest.Utente4!H37) -> 3.5
A40: T3_KS2 | B40: Come valuti la tua competenza nell'uso di strumenti digitali per scoprire e prenotare attività turistiche? | H40: =AVERAGE(Quest.Utente1!H38,Quest.Utente2!H38,Quest.Utente3!H38,Quest.Utente4!H38) -> 3
...

Sheet RISULTATI
A1: Task | B1: ISE | C1: IKS | D1: IPC | E1: IMOT
A2: T1 | B2: =MEDIE!H6 -> 3.75 | C2: =MEDIE!H10 -> 3.6666667 | D2: =MEDIE!H13 -> 4 | E2: =MEDIE!H17 -> 3.4166667
A3: T2 | B3: =MEDIE!H22 -> 3.6666667 | C3: =MEDIE!H26 -> 3.5 | D3: =MEDIE!H29 -> 3.625 | E3: =MEDIE!H33 -> 3.5833333
A4: T3 | B4: =MEDIE!H38 -> 3.25 | C4: =MEDIE!H42 -> 3.3333333 | D4: =MEDIE!H45 -> 3.625 | E4: =MEDIE!H49 -> 2.9166667
